<?xml version='1.0' encoding='UTF-8'?>
<mujoco>

    <option timestep="1e-4"/>
    <option gravity="0 0 -9.8"/>

    <asset>
        <texture type="skybox" builtin="gradient" rgb1="0.8 0.9 1" rgb2="0.2 0.3 0.6" width="265" height="256"/>
        <texture name="grid" type="2d" builtin="checker" rgb1="0.1 0.1 0.1" rgb2="0.3 0.3 0.3" width="300" height="300"/>
        <material name="grid" texture="grid" texrepeat="10 10" reflectance="0.1"/>
    </asset>

    <worldbody>
        <light pos="0 0 10" diffuse="0.8 0.8 0.8" specular="0.5 0.5 0.5"/>
        <light pos="2 2 5" diffuse="0.5 0.5 0.5" specular="0.3 0.3 0.3"/>
        <geom type="plane" size="0.5 0.5 0.1" material="grid"/>

        <!-- Фиксированные точки -->
        <site name="fixed_O" pos="0 0 0.02" size="0.008"/>
        <site name="fixed_C" pos="0.046 0 0.02" size="0.008"/>
        <site name="fixed_D" pos="0.069 0 0.02" size="0.008"/>

        <!-- ОСНОВНАЯ ЦЕПОЧКА O-A-B - КРИВОШИП -->
        <body name="OAB" pos="0 0 0.02" euler="0 0 0">
            <joint name="O" type="hinge" axis="0 -1 0" damping="0.1"/>
            <geom name="point O" type="sphere" pos="0 0 0" size="0.008"/>
            <geom name="link OA" type="cylinder" pos="0.023 0 0" size="0.005 0.023" euler="0 90 0"/>
            <site name="sA" size="0.004" pos="0.046 0 0"/>

            <body name="AB" pos="0.046 0 0" euler="0 0 0">
                <joint name="A" type="ball" damping="0.1"/>
                <geom name="point A" type="sphere" pos="0 0 0" size="0.008"/>
                <geom name="link AB" type="cylinder" pos="0.0299 0 0" size="0.005 0.0299" euler="0 90 0"/>
                <site name="sB" size="0.004" pos="0.0598 0 0"/>
            </body>
        </body>

        <!-- ЗВЕНО C-B - КОРОМЫСЛО -->
        <body name="CB" pos="0.046 0 0.02" euler="0 0 0">
            <joint name="C" type="hinge" axis="0 -1 0" damping="0.1"/>
            <geom name="point C" type="sphere" pos="0 0 0" size="0.008"/>
            <geom name="link CB" type="cylinder" pos="0.0345 0 0" size="0.005 0.0345" euler="0 90 0"/>
            <site name="sB_CB" size="0.004" pos="0.069 0 0"/>
        </body>

        <!-- ЗВЕНО D-B - ДОПОЛНИТЕЛЬНОЕ ЗВЕНО -->
        <body name="DB" pos="0.069 0 0.02" euler="0 0 0">
            <joint name="D" type="hinge" axis="0 -1 0" damping="0.1"/>
            <geom name="point D" type="sphere" pos="0 0 0" size="0.008"/>
            <geom name="link DB" type="cylinder" pos="-0.023 0 0" size="0.005 0.023" euler="0 90 0"/>
            <site name="sB_DB" size="0.004" pos="-0.046 0 0"/>
        </body>

    </worldbody>

    <equality>
        <!-- СОЕДИНЕНИЕ ВСЕХ ТРЕХ ЗВЕНЬЕВ В ТОЧКЕ B -->
        <connect site1="sB" site2="sB_CB"/>
        <connect site1="sB" site2="sB_DB"/>
    </equality>

</mujoco>